{"author":{"id":"79c38be314ca670ea16295527a94796e078306702cedcad4d5750ae51feca4d0"},"ops":[{"type":6,"timestamp":1586548065,"metadata":{"github-id":"MDE1OlVzZXJDb250ZW50RWRpdElzc3VlRWRpdDozNjk3MTQ2ODU="},"nonce":"Y2l2gAN8ChdPysC9JGYGuGnkqDY=","target":"7f555b016af63574c1c218dc759446698f1af2d35553668219013c266684a063","message":"Hi,\n\nPlaying with git-bug on a existing gitlab repository with a few existing issues on the vendor's bug tracker,  I ran trough the following errors:\n\nAfter having successfully configured the bridge I could import the gitlab issues as well as creating a couple of local issues with `git bug add`, so far so good. Then, I meet the following errors:\n* when doing again `git bug bridge pull`, issues are duplicated with new hashes. \n* nothing is exported when doing `git bug bridge push`.\n\nI've tested the bridge on a freshly created repo on gitlab, again the first steps goes well, but this time when doing `git bug bridge` a second time to test if duplicates arise, I got this crash:\n\n```\npanic: runtime error: index out of range [-1]                                                                                                        \n                                                                        \ngoroutine 51 [running]:       \ngithub.com/MichaelMure/git-bug/bridge/gitlab/iterator.(*issueIterator).Value(...)\n        /home/dtrckd/src/_sink/git-bug/bridge/gitlab/iterator/issue.go:38\ngithub.com/MichaelMure/git-bug/bridge/gitlab/iterator.(*Iterator).NextIssue(0xc0010ba000, 0xc000043dd0)\n        /home/dtrckd/src/_sink/git-bug/bridge/gitlab/iterator/iterator.go:86 +0x244\ngithub.com/MichaelMure/git-bug/bridge/gitlab.(*gitlabImporter).ImportAll.func1(0xc000260100, 0xc0000aed00, 0xc0010bc000)\n        /home/dtrckd/src/_sink/git-bug/bridge/gitlab/import.go:70 +0x547\ncreated by github.com/MichaelMure/git-bug/bridge/gitlab.(*gitlabImporter).ImportAll\n        /home/dtrckd/src/_sink/git-bug/bridge/gitlab/import.go:66 +0x146\n\n```\nSimilar scenario on Github seems to work fine.\n\nVersion:\ngit-bug version: 0.7.1-dev-28c3ee3b71\ngithub.com/xanzy/go-gitlab v0.29.0\ngo version go1.14.1 linux/amd64\n\nGitlab: 12.9.2 (self hosted)\nOS: Linux 4.19.0-8-amd64 / Debian 10 x86_64","files":null},{"type":6,"timestamp":1586548210,"metadata":{"github-id":"MDE1OlVzZXJDb250ZW50RWRpdElzc3VlRWRpdDozNjk3MTUyNDE="},"nonce":"CLQSriM8omKNkj+/dJpz6mEKWDM=","target":"7f555b016af63574c1c218dc759446698f1af2d35553668219013c266684a063","message":"Hi,\n\nPlaying with git-bug on a existing gitlab repository with a few existing issues on the vendor's bug tracker,  I ran trough the following errors:\n\nAfter having successfully configured the bridge I could import the gitlab issues as well as creating a couple of local issues with `git bug add`, so far so good. Then, I meet the following errors:\n* when doing again `git bug bridge pull`, issues are duplicated with new hashes. \n* nothing is exported when doing `git bug bridge push`, it jus returns `exported 0 issues with myBridge bridge`.\n\nI've tested the bridge on a freshly created repo on gitlab, again the first steps goes well, but this time when doing `git bug bridge` a second time to test if duplicates arise, I got this crash:\n\n```\npanic: runtime error: index out of range [-1]                                                                                                        \n                                                                        \ngoroutine 51 [running]:       \ngithub.com/MichaelMure/git-bug/bridge/gitlab/iterator.(*issueIterator).Value(...)\n        /home/dtrckd/src/_sink/git-bug/bridge/gitlab/iterator/issue.go:38\ngithub.com/MichaelMure/git-bug/bridge/gitlab/iterator.(*Iterator).NextIssue(0xc0010ba000, 0xc000043dd0)\n        /home/dtrckd/src/_sink/git-bug/bridge/gitlab/iterator/iterator.go:86 +0x244\ngithub.com/MichaelMure/git-bug/bridge/gitlab.(*gitlabImporter).ImportAll.func1(0xc000260100, 0xc0000aed00, 0xc0010bc000)\n        /home/dtrckd/src/_sink/git-bug/bridge/gitlab/import.go:70 +0x547\ncreated by github.com/MichaelMure/git-bug/bridge/gitlab.(*gitlabImporter).ImportAll\n        /home/dtrckd/src/_sink/git-bug/bridge/gitlab/import.go:66 +0x146\n\n```\nSimilar scenario on Github seems to work fine.\n\nVersion:\ngit-bug version: 0.7.1-dev-28c3ee3b71\ngithub.com/xanzy/go-gitlab v0.29.0\ngo version go1.14.1 linux/amd64\n\nGitlab: 12.9.2 (self hosted)\nOS: Linux 4.19.0-8-amd64 / Debian 10 x86_64","files":null},{"type":6,"timestamp":1586609211,"metadata":{"github-id":"MDE1OlVzZXJDb250ZW50RWRpdElzc3VlRWRpdDozNjk4MzA1ODM="},"nonce":"pWSBPBHSSBomNQl0q7rq2kUrrJg=","target":"7f555b016af63574c1c218dc759446698f1af2d35553668219013c266684a063","message":"Hi,\n\nPlaying with git-bug on a existing gitlab repository with a few existing issues on the vendor's bug tracker,  I ran trough the following errors:\n\nAfter having successfully configured the bridge I could import the gitlab issues as well as creating a couple of local issues with `git bug add`, so far so good. Then, I meet the following errors:\n* when doing again `git bug bridge pull`, issues are duplicated with new hashes. \n* nothing is exported when doing `git bug bridge push`, it jus returns `exported 0 issues with myBridge bridge`.\n\nI've tested the bridge on a freshly created repo on gitlab, again the first steps goes well, but this time when doing `git bug bridge pull` a second time to test if duplicates arise, I got this crash:\n\n```\npanic: runtime error: index out of range [-1]                                                                                                        \n                                                                        \ngoroutine 51 [running]:       \ngithub.com/MichaelMure/git-bug/bridge/gitlab/iterator.(*issueIterator).Value(...)\n        /home/dtrckd/src/_sink/git-bug/bridge/gitlab/iterator/issue.go:38\ngithub.com/MichaelMure/git-bug/bridge/gitlab/iterator.(*Iterator).NextIssue(0xc0010ba000, 0xc000043dd0)\n        /home/dtrckd/src/_sink/git-bug/bridge/gitlab/iterator/iterator.go:86 +0x244\ngithub.com/MichaelMure/git-bug/bridge/gitlab.(*gitlabImporter).ImportAll.func1(0xc000260100, 0xc0000aed00, 0xc0010bc000)\n        /home/dtrckd/src/_sink/git-bug/bridge/gitlab/import.go:70 +0x547\ncreated by github.com/MichaelMure/git-bug/bridge/gitlab.(*gitlabImporter).ImportAll\n        /home/dtrckd/src/_sink/git-bug/bridge/gitlab/import.go:66 +0x146\n\n```\nSimilar scenario on Github seems to work fine.\n\nVersion:\ngit-bug version: 0.7.1-dev-28c3ee3b71\ngithub.com/xanzy/go-gitlab v0.29.0\ngo version go1.14.1 linux/amd64\n\nGitlab: 12.9.2 (self hosted)\nOS: Linux 4.19.0-8-amd64 / Debian 10 x86_64","files":null},{"type":3,"timestamp":1586562076,"metadata":{"github-id":"MDEyOklzc3VlQ29tbWVudDYxMjI2NzQ0Mg==","github-url":"https://github.com/MichaelMure/git-bug/issues/366#issuecomment-612267442"},"nonce":"yScIX4hvYRelhnOp0esMPLNTUsk=","message":"New test result: \nWhen using git-bug bridge by pushing bug to remote first, it works. Then If we create an issue on Gitlab and import it, the same scenario as before, firts time ok, then I got the crash (+ the doublon), and bridge push doesn't push new local bug anymore.","files":null},{"type":6,"timestamp":1586609409,"metadata":{"github-id":"MDE1OlVzZXJDb250ZW50RWRpdElzc3VlQ29tbWVudEVkaXQ6MzY0NTI2NjQ2"},"nonce":"Aw1V0IJMw3bXnGVtlZqnjo6CKuo=","target":"d94dbc0e529255b3f01e21da5def22876130009db0d83fa3c4784bcb480ab146","message":"New test result: \nWhen using git-bug bridge by pushing bugs to remote **before** pulling, bug are exported. Then If we create an issue on Gitlab and import, the first time import is ok, then I got the crash (+ the doublon), and bridge push doesn't push new local bug anymore.","files":null}]}